Workbook

Sheet PANEL
A1: PANEL — BOT DE TRADING · puerta del mes (GM): 1 de septiembre de 2026
A3: FASE | B3: TAREAS | C3: HECHAS | D3: EN CURSO | E3: PENDIENTES | F3: BLOQUEADAS | G3: % AVANCE
A4: 01. Arranque | B4: =COUNTIFS(TAREAS!$A$5:$A$63,"01.??.??") | C4: =COUNTIFS(TAREAS!$A$5:$A$63,"01.??.??",TAREAS!$E$5:$E$63,"Hecha") | D4: =COUNTIFS(TAREAS!$A$5:$A$63,"01.??.??",TAREAS!$E$5:$E$63,"En curso") | E4: =COUNTIFS(TAREAS!$A$5:$A$63,"01.??.??",TAREAS!$E$5:$E$63,"Pendiente") | F4: =COUNTIFS(TAREAS!$A$5:$A$63,"01.??.??",TAREAS!$E$5:$E$63,"Bloqueada") | G4: =IFERROR(C4/B4,0)
A5: 02. Elegir mercado y tamaño de vela | B5: =COUNTIFS(TAREAS!$A$5:$A$63,"02.??.??") | C5: =COUNTIFS(TAREAS!$A$5:$A$63,"02.??.??",TAREAS!$E$5:$E$63,"Hecha") | D5: =COUNTIFS(TAREAS!$A$5:$A$63,"02.??.??",TAREAS!$E$5:$E$63,"En curso") | E5: =COUNTIFS(TAREAS!$A$5:$A$63,"02.??.??",TAREAS!$E$5:$E$63,"Pendiente") | F5: =COUNTIFS(TAREAS!$A$5:$A$63,"02.??.??",TAREAS!$E$5:$E$63,"Bloqueada") | G5: =IFERROR(C5/B5,0)
A6: 03. Montar la casa | B6: =COUNTIFS(TAREAS!$A$5:$A$63,"03.??.??") | C6: =COUNTIFS(TAREAS!$A$5:$A$63,"03.??.??",TAREAS!$E$5:$E$63,"Hecha") | D6: =COUNTIFS(TAREAS!$A$5:$A$63,"03.??.??",TAREAS!$E$5:$E$63,"En curso") | E6: =COUNTIFS(TAREAS!$A$5:$A$63,"03.??.??",TAREAS!$E$5:$E$63,"Pendiente") | F6: =COUNTIFS(TAREAS!$A$5:$A$63,"03.??.??",TAREAS!$E$5:$E$63,"Bloqueada") | G6: =IFERROR(C6/B6,0)
A7: 04. Hipótesis y validación | B7: =COUNTIFS(TAREAS!$A$5:$A$63,"04.??.??") | C7: =COUNTIFS(TAREAS!$A$5:$A$63,"04.??.??",TAREAS!$E$5:$E$63,"Hecha") | D7: =COUNTIFS(TAREAS!$A$5:$A$63,"04.??.??",TAREAS!$E$5:$E$63,"En curso") | E7: =COUNTIFS(TAREAS!$A$5:$A$63,"04.??.??",TAREAS!$E$5:$E$63,"Pendiente") | F7: =COUNTIFS(TAREAS!$A$5:$A$63,"04.??.??",TAREAS!$E$5:$E$63,"Bloqueada") | G7: =IFERROR(C7/B7,0)
A8: 05. Demo | B8: =COUNTIFS(TAREAS!$A$5:$A$63,"05.??.??") | C8: =COUNTIFS(TAREAS!$A$5:$A$63,"05.??.??",TAREAS!$E$5:$E$63,"Hecha") | D8: =COUNTIFS(TAREAS!$A$5:$A$63,"05.??.??",TAREAS!$E$5:$E$63,"En curso") | E8: =COUNTIFS(TAREAS!$A$5:$A$63,"05.??.??",TAREAS!$E$5:$E$63,"Pendiente") | F8: =COUNTIFS(TAREAS!$A$5:$A$63,"05.??.??",TAREAS!$E$5:$E$63,"Bloqueada") | G8: =IFERROR(C8/B8,0)
A9: 06. Real | B9: =COUNTIFS(TAREAS!$A$5:$A$63,"06.??.??") | C9: =COUNTIFS(TAREAS!$A$5:$A$63,"06.??.??",TAREAS!$E$5:$E$63,"Hecha") | D9: =COUNTIFS(TAREAS!$A$5:$A$63,"06.??.??",TAREAS!$E$5:$E$63,"En curso") | E9: =COUNTIFS(TAREAS!$A$5:$A$63,"06.??.??",TAREAS!$E$5:$E$63,"Pendiente") | F9: =COUNTIFS(TAREAS!$A$5:$A$63,"06.??.??",TAREAS!$E$5:$E$63,"Bloqueada") | G9: =IFERROR(C9/B9,0)
A10: 07. Motor y orden | B10: =COUNTIFS(TAREAS!$A$5:$A$63,"07.??.??") | C10: =COUNTIFS(TAREAS!$A$5:$A$63,"07.??.??",TAREAS!$E$5:$E$63,"Hecha") | D10: =COUNTIFS(TAREAS!$A$5:$A$63,"07.??.??",TAREAS!$E$5:$E$63,"En curso") | E10: =COUNTIFS(TAREAS!$A$5:$A$63,"07.??.??",TAREAS!$E$5:$E$63,"Pendiente") | F10: =COUNTIFS(TAREAS!$A$5:$A$63,"07.??.??",TAREAS!$E$5:$E$63,"Bloqueada") | G10: =IFERROR(C10/B10,0)
A11: TOTAL PROYECTO | B11: =SUM(B4:B10) | C11: =SUM(C4:C10) | D11: =SUM(D4:D10) | E11: =SUM(E4:E10) | F11: =SUM(F4:F10) | G11: =IFERROR(C11/B11,0)
A13: ESTADO DE HOY (leido de WBS.md)
A14: CODIGO | B14: TAREA | G14: ESTADO
A15: 01.01.01 | B15: Aprobar plan y reglas | G15: En curso
A16: 02.02.02 | B16: Coste relativo: coste ÷ movimiento medio, en % (el número clave). Coste de USDJPY corregido a 1,16 pips | G16: Bloqueada
A17: 02.03.01 | B17: Revisión independiente de método, fuentes y números | G17: En curso
A19: PROXIMA PUERTA | B19: G1 — elegir mercado y tamaño de vela (criterios en la hoja PUERTAS)
A20: OBJETIVO DEL MES | B20: Llegar al 1 de septiembre con respuesta a: ¿existe alguna estrategia que merezca pasar a demo?
A21: FUENTE DE VERDAD | B21: 00-direccion/WBS.md — este Excel se genera de ahi. Si discrepan, manda el texto.
A25: LEYENDA
A26: Hecha
A27: En curso
A28: Pendiente
A29: Bloqueada

Sheet SIGUIENTE
A1: QUE SE HACE AHORA Y EN QUE ORDEN
A2: Orden calculado de WBS.md: (1) una tarea entra en la cola cuando TODAS sus dependencias estan hechas; (2) primero lo ya empezado; (3) despues el PRODUCTO antes que el MOTOR (regla 12: el motor no manda); (4) a igualdad, orden de codigo WBS (regla 4). MOTOR = fases 03 y 07 y lo que su texto marque como tal. DESBLOQUEA = tareas vivas que la esperan directamente · EN CADENA = todas las que quedan detras contando el efecto domino.
A4: AHORA — EQUIPO | C4: 01.02.02 — Trasplante pieza a pieza desde gb2 (D6=B). Una tarea por pieza, cada una con su criterio de aceptación (ver sección Trasplante). Ninguna entra sin pasar su prueba ejecutada | I4: Crítico + Constructores
A5: AHORA — CEO | C5: 01.01.01 — Aprobar plan y reglas | I5: CEO
A6: CUELLO DE BOTELLA | C6: 01.01.01 — Aprobar plan y reglas. Detras de ella esperan 27 de las 44 tareas vivas. | I6: CEO
A8: ORDEN | B8: CODIGO | C8: QUE HAY QUE HACER | D8: QUIEN | E8: CARRIL | F8: ESTADO | G8: DESBLOQUEA | H8: EN CADENA | I8: QUE FALTA PARA PODER EMPEZARLA
A9: SE PUEDE TRABAJAR YA — 11 tareas, en este orden
A10: 1 | B10: 01.01.01 | C10: Aprobar plan y reglas | D10: CEO | E10: PRODUCTO | F10: En curso | G10: 2 | H10: 27 | I10: nada: se puede empezar ya
A11: 2 | B11: 01.02.02 | C11: Trasplante pieza a pieza desde gb2 (D6=B). Una tarea por pieza, cada una con su criterio de aceptación (ver sección Trasplante). Ninguna entra sin pasar su prueba ejecutada | D11: Crítico + Constructores | E11: PRODUCTO | F11: Pendiente | I11: nada: se puede empezar ya
A12: 3 | B12: 04.02.01 | C12: Barrido de fuentes: papers, libros, foros, GitHub, X. Regla: mínimo 2 fuentes independientes verificables por idea; vendedores de cursos/señales no son fuente | D12: Investigador | E12: PRODUCTO | F12: Pendiente | G12: 1 | H12: 16 | I12: nada: se puede empezar ya
A13: 4 | B13: 01.02.03 | C13: Auditar el catálogo awesome-claude-code y proponer máximo 4 piezas concretas para el motor, con motivo y coste de integración. Carril de motor: cuenta contra el 20% y se limita a 1 tirada | D13: Investigador | E13: MOTOR | F13: Pendiente | I13: nada: se puede empezar ya
A14: 5 | B14: 03.01.03 | C14: Ejecución desatendida: arranques programados, permisos AMPLIOS por defecto (git como red de seguridad) y topes de gasto | D14: Constructores | E14: MOTOR | F14: Pendiente | G14: 2 | H14: 2 | I14: nada: se puede empezar ya
A15: 6 | B15: 03.01.04 | C15: Plan de respaldo de modelos: si un modelo no está disponible o rechaza, el agente sigue con su respaldo y lo anota | D15: Constructores | E15: MOTOR | F15: Pendiente | G15: 1 | H15: 1 | I15: nada: se puede empezar ya
A16: 7 | B16: 03.01.06 | C16: Plantilla y automatismo de fichas de decisión: el secretario prepara cada decisión del CEO en el formato obligatorio y la adjunta al informe semanal | D16: Secretario | E16: MOTOR | F16: Pendiente | G16: 1 | H16: 1 | I16: nada: se puede empezar ya
A17: 8 | B17: 03.01.09 | C17: Enrutado por tipo de tarea y comprobación de que el WBS genera tareas de cada tipo de agente (regla 26) | D17: Constructores | E17: MOTOR | F17: Pendiente | I17: nada: se puede empezar ya
A18: 9 | B18: 03.01.10 | C18: Testbed sintético de invarianza: resultado de referencia fijo que debe reproducirse tras cualquier cambio del motor | D18: Constructores | E18: MOTOR | F18: Pendiente | I18: nada: se puede empezar ya
A19: 10 | B19: 07.01.01 | C19: Carpetas y documentos en orden; una fuente de verdad por tema; lo sustituido se borra | D19: Constructores | E19: MOTOR | F19: Pendiente | I19: nada: se puede empezar ya
A20: 11 | B20: 07.01.02 | C20: Mejoras del motor: SOLO tareas aprobadas en revisión semanal (el motor no manda) | D20: Constructores | E20: MOTOR | F20: Pendiente | I20: nada: se puede empezar ya
A21: ESPERANDO A OTRA TAREA — 33 tareas, en orden de codigo WBS
A22: — | B22: 01.01.02 | C22: Aprobar criterios de la puerta G1 | D22: CEO | E22: PRODUCTO | F22: Pendiente | G22: 1 | H22: 25 | I22: 01.01.01 (en curso, CEO)
A23: — | B23: 01.01.03 | C23: Fijar límites: fecha tope, horas CEO/semana, pérdida máxima futura | D23: CEO | E23: PRODUCTO | F23: Pendiente | I23: 01.01.01 (en curso, CEO)
A24: — | B24: 02.01.01 | C24: Confirmar 8 candidatos: EURUSD, GBPUSD, USDJPY, AUDUSD, USDCHF, XAUUSD, BTC, ETH | D24: CEO + Orquestador | E24: PRODUCTO | F24: Pendiente | G24: 4 | H24: 24 | I24: 01.01.02 (pendiente, CEO)
A25: — | B25: 02.01.02 | C25: Costes típicos de operar por mercado (PROVISIONAL hasta 04.01.02) | D25: Investigador | E25: PRODUCTO | F25: Pendiente | G25: 1 | H25: 20 | I25: 02.01.01 (pendiente, CEO + Orquestador)
A26: — | B26: 02.02.01 | C26: CORREGIDA 29/07: descargar precios y CALCULAR el ATR de 15m, 1h y 4h (no buscarlo publicado: no existe). Script atr_local.py | D26: Constructor de datos | E26: PRODUCTO | F26: Pendiente | G26: 2 | H26: 20 | I26: 02.01.01 (pendiente, CEO + Orquestador)
A27: — | B27: 02.02.02 | C27: Coste relativo: coste ÷ movimiento medio, en % (el número clave). Coste de USDJPY corregido a 1,16 pips | D27: Constructor de datos | E27: PRODUCTO | F27: Bloqueada | G27: 1 | H27: 19 | I27: 02.01.02 (pendiente, Investigador), 02.02.01 (pendiente, Constructor de datos)
A28: — | B28: 02.02.03 | C28: CORREGIDA 30/07: CALCULAR la matriz de correlaciones en 3 ventanas (3 meses, 1 año, 2 años) con hora de corte única (22:00 UTC) y en la vela elegida, no solo diaria. No existe publicada de forma homogénea | D28: Constructor de datos | E28: PRODUCTO | F28: Pendiente | G28: 1 | H28: 19 | I28: 02.01.01 (pendiente, CEO + Orquestador)
A29: — | B29: 02.02.05 | C29: NUEVA: coste de mantener posición de un día para otro (swap/financiación) en los 8 instrumentos, 2-3 brokers. En cripto CFD puede superar varias veces al spread | D29: Investigador | E29: PRODUCTO | F29: Pendiente | G29: 1 | H29: 19 | I29: 02.01.01 (pendiente, CEO + Orquestador)
A30: — | B30: 02.03.01 | C30: Revisión independiente de método, fuentes y números | D30: Orquestador | E30: PRODUCTO | F30: En curso | G30: 1 | H30: 18 | I30: 02.02.01 (pendiente, Constructor de datos), 02.02.02 (bloqueada, Constructor de datos), 02.02.03 (pendiente, Constructor de datos), 02.02.05 (pendiente, Investigador)
A31: — | B31: 02.03.02 | C31: Informe de decisión: 3-5 mercados poco correlacionados + 1-2 velas | D31: Orquestador | E31: PRODUCTO | F31: Pendiente | G31: 1 | H31: 17 | I31: 02.03.01 (en curso, Orquestador)
A32: — | B32: 02.03.03 | C32: PUERTA G1: el CEO elige | D32: CEO | E32: PRODUCTO | F32: Pendiente | G32: 1 | H32: 16 | I32: 02.03.02 (pendiente, Orquestador)
A33: — | B33: 03.01.05 | C33: PRUEBA REAL DEL MOTOR: un día entero de trabajo desatendido de verdad antes de dar la fase por buena | D33: Orquestador | E33: MOTOR | F33: Pendiente | I33: 03.01.03 (pendiente, Constructores), 03.01.04 (pendiente, Constructores)
A34: — | B34: 03.01.07 | C34: Cola de aprobación del CEO: tabla con desplegable Aprobado / Saltar / Corregir y columna de corrección. Lo aprobado se ejecuta solo; lo corregido se rehace Y la corrección se guarda en LECCIONES.md | D34: Secretario | E34: MOTOR | F34: Pendiente | I34: 03.01.06 (pendiente, Secretario)
A35: — | B35: 03.01.08 | C35: Prueba de fuego de las barreras (regla 13): inyectar cada caso prohibido —leer el cajón reservado, escribir fuera del proyecto, borrar datos, gastar dinero— y comprobar que se bloquea de verdad. Lo que no se bloquee se marca "no verificada" | D35: Crítico | E35: MOTOR | F35: Pendiente | I35: 03.01.03 (pendiente, Constructores)
A36: — | B36: 04.01.01 | C36: Comparar 3-4 brokers del mercado elegido; elegir uno y abrir demo (CEO firma) | D36: CEO + Orquestador | E36: PRODUCTO | F36: Pendiente | G36: 2 | H36: 15 | I36: 02.03.03 (pendiente, CEO)
A37: — | B37: 04.01.02 | C37: Recalcular costes con precios reales del broker (sustituye 02.01.02) | D37: Constructor datos | E37: PRODUCTO | F37: Pendiente | I37: 04.01.01 (pendiente, CEO + Orquestador)
A38: — | B38: 04.01.03 | C38: Histórico limpio partido en 3 cajones: construir (train), ajustar (validación) y RESERVADO bajo llave (OOS, se abre una sola vez por variante). Ningún agente toca el reservado | D38: Constructor datos | E38: PRODUCTO | F38: Pendiente | G38: 1 | H38: 13 | I38: 04.01.01 (pendiente, CEO + Orquestador)
A39: — | B39: 04.02.02 | C39: Ficha por hipótesis: por qué existiría la ventaja, reglas de entrada/salida, mercado y vela. Sin lógica de por qué gana, no entra (nada de probar por probar) | D39: Investigador | E39: PRODUCTO | F39: Pendiente | G39: 1 | H39: 15 | I39: 04.02.01 (pendiente, Investigador)
A40: — | B40: 04.02.03 | C40: Filtro de sentido: el Validador puntúa y se eligen las 3-5 mejores | D40: Validador | E40: PRODUCTO | F40: Pendiente | G40: 1 | H40: 14 | I40: 04.02.02 (pendiente, Investigador)
A41: — | B41: 04.02.04 | C41: Pre-registro de variantes: cada hipótesis deja escritas sus variantes ANTES de probar (máx. 5-7 por hipótesis). Lo no registrado no se prueba | D41: Validador | E41: PRODUCTO | F41: Pendiente | G41: 1 | H41: 13 | I41: 04.02.03 (pendiente, Validador)
A42: — | B42: 04.03.01 | C42: Backtest con costes reales sobre el cajón de construir | D42: Constructores | E42: PRODUCTO | F42: Pendiente | G42: 1 | H42: 12 | I42: 04.01.03 (pendiente, Constructor datos), 04.02.04 (pendiente, Validador)
...

Sheet TAREAS
A1: TODAS LAS TAREAS — WBS v0.9 · generado de 00-direccion/WBS.md
A2: Una fila por tarea. Filtra por ESTADO con la flecha de la cabecera. Verde = hecha · amarillo = en curso · rojo = bloqueada. Las tareas del CEO llevan la columna RESPONSABLE en naranja.
A4: CODIGO | B4: QUE SE HACE | C4: RESPONSABLE | D4: DEPENDE DE | E4: ESTADO | F4: DETALLE / DONDE ESTA
A5: 01 | B5: ARRANQUE (PUERTA G0)
A6: 01.01.01 | B6: Aprobar plan y reglas | C6: CEO | D6: — | E6: En curso
A7: 01.01.02 | B7: Aprobar criterios de la puerta G1 | C7: CEO | D7: 01.01.01 | E7: Pendiente
A8: 01.01.03 | B8: Fijar límites: fecha tope, horas CEO/semana, pérdida máxima futura | C8: CEO | D8: 01.01.01 | E8: Pendiente
A9: 01.02.01 | B9: Analizar gb2 como información (no copia) | C9: Crítico | D9: 01.01.01 | E9: Hecha | F9: 30/07 — INFORME_GB2.md
A10: 01.02.02 | B10: Trasplante pieza a pieza desde gb2 (D6=B). Una tarea por pieza, cada una con su criterio de aceptación (ver sección Trasplante). Ninguna entra sin pasar su prueba ejecutada | C10: Crítico + Constructores | D10: 03.01.01 | E10: Pendiente
A11: 01.02.03 | B11: Auditar el catálogo awesome-claude-code y proponer máximo 4 piezas concretas para el motor, con motivo y coste de integración. Carril de motor: cuenta contra el 20% y se limita a 1 tirada | C11: Investigador | D11: 03.01.02 | E11: Pendiente
A12: 02 | B12: ELEGIR MERCADO Y TAMAÑO DE VELA (PUERTA G1)
A13: 02.01.01 | B13: Confirmar 8 candidatos: EURUSD, GBPUSD, USDJPY, AUDUSD, USDCHF, XAUUSD, BTC, ETH | C13: CEO + Orquestador | D13: 01.01.02 | E13: Pendiente | F13: los 8 candidatos ya se usan de hecho en 02.02.04 (hecha) y en los briefs A y B; falta ratificación formal del CEO en G1
A14: 02.01.02 | B14: Costes típicos de operar por mercado (PROVISIONAL hasta 04.01.02) | C14: Investigador | D14: 02.01.01 | E14: Pendiente
A15: 02.02.01 | B15: CORREGIDA 29/07: descargar precios y CALCULAR el ATR de 15m, 1h y 4h (no buscarlo publicado: no existe). Script atr_local.py | C15: Constructor de datos | D15: 02.01.01 | E15: Pendiente | F15: script atr_local.py escrito (142 líneas, en git) pero NUNCA EJECUTADO: 02-datos/bruto/ vacío, no existe atr_real.json. Su ficha debe fijar antes fuente de datos (el script usa Yahoo/yfinance; 02.02.04 concluyó Dukascopy/HistData/TrueFX/Binance/Kraken) y tratamiento del oro (el script usa el futuro GC=F; L-007 dice que no es XAUUSD al contado)
A16: 02.02.02 | B16: Coste relativo: coste ÷ movimiento medio, en % (el número clave). Coste de USDJPY corregido a 1,16 pips | C16: Constructor de datos | D16: 02.01.02, 02.02.01 | E16: Bloqueada | F16: depende de 02.01.02 (pendiente) y de 02.02.01 (sin ejecutar). El coste de USDJPY corregido a 1,16 pips viene de revision_brief_A.md
A17: 02.02.03 | B17: CORREGIDA 30/07: CALCULAR la matriz de correlaciones en 3 ventanas (3 meses, 1 año, 2 años) con hora de corte única (22:00 UTC) y en la vela elegida, no solo diaria. No existe publicada de forma homogénea | C17: Constructor de datos | D17: 02.01.01 | E17: Pendiente | F17: sin artefacto: no hay matriz calculada ni script. Reutilizará los precios que descargue 02.02.01
A18: 02.02.04 | B18: Historial disponible: años, fuente, coste | C18: Investigador | D18: 02.01.01 | E18: Hecha | F18: Dukascopy (tick desde 2003, forex y oro al contado), HistData, TrueFX, Binance, Kraken. Todo gratis, muy por encima de los 5 años exigidos
A19: 02.02.05 | B19: NUEVA: coste de mantener posición de un día para otro (swap/financiación) en los 8 instrumentos, 2-3 brokers. En cripto CFD puede superar varias veces al spread | C19: Investigador | D19: 02.01.01 | E19: Pendiente
A20: 02.03.01 | B20: Revisión independiente de método, fuentes y números | C20: Orquestador | D20: 02.02.* | E20: En curso | F20: revisados Brief A (revision_brief_A.md, 29/07) y Brief B (revision_brief_B.md, 30/07). No se cierra hasta que 02.02.* entreguen números. ("parcial" no era un estado legal)
A21: 02.03.02 | B21: Informe de decisión: 3-5 mercados poco correlacionados + 1-2 velas | C21: Orquestador | D21: 02.03.01 | E21: Pendiente
A22: 02.03.03 | B22: PUERTA G1: el CEO elige | C22: CEO | D22: 02.03.02 | E22: Pendiente
A23: 03 | B23: MONTAR LA CASA (CLAUDE CODE) — EN PARALELO CON LA FASE 02
A24: 03.01.01 | B24: Repositorio: carpetas, WBS texto, CLAUDE.md, DECISIONES.md, LECCIONES.md | C24: Constructores | D24: 01.01.01 | E24: Hecha | F24: 30/07 — repo completo: carpetas, WBS, CLAUDE.md, DECISIONES.md, LECCIONES.md, plantillas y .gitignore (42 ficheros en git). AVISO regla 24 NO VERIFICADA: la prueba de inyección de datos no se ha ejecutado; 02-datos/ está vacío. Se ejecuta al bajar los primeros precios en 02.02.01
A25: 03.01.02 | B25: Crear TODOS los agentes del Equipo, cada uno con su modelo y descripción sin ambigüedad; prueba de activación de todos (ningún agente fantasma) | C25: Constructores | D25: 03.01.01, 01.02.01 | E25: Hecha | F25: 30/07 — 8 agentes en .claude/agents/, cada uno con identificador exacto de modelo y respaldo. Prueba de activación ejecutada 30/07: los 8 respondieron y leyeron un fichero real, ningún fantasma. LÍMITE: la prueba no demuestra que el modelo enrutado sea el de la ficha; se verifica en 03.01.04, con atención a claude-fable-5 (validador y arquitecto)
A26: 03.01.03 | B26: Ejecución desatendida: arranques programados, permisos AMPLIOS por defecto (git como red de seguridad) y topes de gasto | C26: Constructores | D26: 03.01.02 | E26: Pendiente
A27: 03.01.04 | B27: Plan de respaldo de modelos: si un modelo no está disponible o rechaza, el agente sigue con su respaldo y lo anota | C27: Constructores | D27: 03.01.02 | E27: Pendiente
A28: 03.01.05 | B28: PRUEBA REAL DEL MOTOR: un día entero de trabajo desatendido de verdad antes de dar la fase por buena | C28: Orquestador | D28: 03.01.03, 03.01.04 | E28: Pendiente
A29: 03.01.06 | B29: Plantilla y automatismo de fichas de decisión: el secretario prepara cada decisión del CEO en el formato obligatorio y la adjunta al informe semanal | C29: Secretario | D29: 03.01.02 | E29: Pendiente
A30: 03.01.07 | B30: Cola de aprobación del CEO: tabla con desplegable Aprobado / Saltar / Corregir y columna de corrección. Lo aprobado se ejecuta solo; lo corregido se rehace Y la corrección se guarda en LECCIONES.md | C30: Secretario | D30: 03.01.06 | E30: Pendiente
A31: 03.01.08 | B31: Prueba de fuego de las barreras (regla 13): inyectar cada caso prohibido —leer el cajón reservado, escribir fuera del proyecto, borrar datos, gastar dinero— y comprobar que se bloquea de verdad. Lo que no se bloquee se marca "no verificada" | C31: Crítico | D31: 03.01.03 | E31: Pendiente
A32: 03.01.09 | B32: Enrutado por tipo de tarea y comprobación de que el WBS genera tareas de cada tipo de agente (regla 26) | C32: Constructores | D32: 03.01.02 | E32: Pendiente
A33: 03.01.10 | B33: Testbed sintético de invarianza: resultado de referencia fijo que debe reproducirse tras cualquier cambio del motor | C33: Constructores | D33: 03.01.01 | E33: Pendiente
A34: 04 | B34: HIPÓTESIS Y VALIDACIÓN (PUERTA G2)
A35: 04.01 | B35: Broker y cajones de datos
A36: 04.01.01 | B36: Comparar 3-4 brokers del mercado elegido; elegir uno y abrir demo (CEO firma) | C36: CEO + Orquestador | D36: 02.03.03 | E36: Pendiente
A37: 04.01.02 | B37: Recalcular costes con precios reales del broker (sustituye 02.01.02) | C37: Constructor datos | D37: 04.01.01 | E37: Pendiente
A38: 04.01.03 | B38: Histórico limpio partido en 3 cajones: construir (train), ajustar (validación) y RESERVADO bajo llave (OOS, se abre una sola vez por variante). Ningún agente toca el reservado | C38: Constructor datos | D38: 04.01.01 | E38: Pendiente
A39: 04.02 | B39: Investigación de hipótesis
A40: 04.02.01 | B40: Barrido de fuentes: papers, libros, foros, GitHub, X. Regla: mínimo 2 fuentes independientes verificables por idea; vendedores de cursos/señales no son fuente | C40: Investigador | D40: 03.01.02 | E40: Pendiente
A41: 04.02.02 | B41: Ficha por hipótesis: por qué existiría la ventaja, reglas de entrada/salida, mercado y vela. Sin lógica de por qué gana, no entra (nada de probar por probar) | C41: Investigador | D41: 04.02.01 | E41: Pendiente
...

Sheet CALENDARIO
A1: CALENDARIO — 29 julio a 1 septiembre de 2026
A2: Objetivo del mes: NO es tener el bot en demo. Es llegar al 1 de septiembre con respuesta a "¿existe alguna estrategia que merezca pasar a demo?".
A4: Semana | B4: Fechas | C4: Qué se hace | D4: Hecho al final | E4: Lunes del CEO (1 h)
A5: S1 | B5: 29 jul – 4 ago | C5: Fase 02 completa + 01.02.01 (gb2) + 03.01.01 (repo), en paralelo | D5: Mercado y vela elegidos (G1) | E5: Lun 3: leer informe G1 y elegir
A6: S2 | B6: 5 – 11 ago | C6: 03.01.02 a 03.01.06 + 04.01.01 (broker) | D6: Motor solo 24 h sin caerse + broker | E6: Lun 10: firmar broker
A7: S3 | B7: 12 – 18 ago | C7: 04.01.02, 04.01.03 + 04.02.01 a 04.02.04 | D7: 3-5 hipótesis con variantes pre-registradas | E7: Lun 17: ver hipótesis
A8: S4 | B8: 19 – 25 ago | C8: 04.03.01, 04.03.02 | D8: Variantes supervivientes tras ajuste | E8: Lun 24: cuántas siguen vivas
A9: S5 | B9: 26 ago – 1 sept | C9: 04.03.03 a 04.03.05 + 04.04.01 | D9: Veredicto pasa/no pasa por variante | E9: Lun 31: preparar evaluación
A10: GM | B10: 1 sept | C10: Puerta del mes con el CEO | D10: Arrancar demo / otra vuelta / replantear | E10: Mar 1: la reunión
A12: Lo que NO cabe en el mes: la demo (8-12 semanas de mercado real, reloj no acelerable) · las 3 vueltas del bucle (cabe una y media) · el dinero real.

Sheet PUERTAS
A1: PUERTAS — donde decide el CEO
A2: Criterios tal y como estan escritos en WBS.md (G1 corregida el 30/07/2026).
A4: PUERTA | B4: QUE SE DECIDE Y CON QUE CRITERIO
A5: G0 | B5: (en curso): CEO aprueba plan, criterios y límites (01.01.01–03).
A6: G1 | B6: (criterios corregidos 30/07): coste de entrar y salir ≤10-15% del movimiento medio de vela y coste de mantener posición medido aparte · cientos de operaciones posibles · datos suficientes (deja de discriminar: hay 20+ años gratis para todos) · correlación que no supere 0,7 en ninguna de las tres ventanas (3 meses, 1 año, 2 años), medida en la vela elegida y con hora de corte única · operable sin nadie delante. Aviso: parte de la correlación entre pares de divisas es aritmética por compartir el dólar (EURUSD/USDCHF: -0,97), así que 5 pares de forex no son 5 apuestas.
A7: G2 | B7: solo pasan variantes que ganan después de costes en OOS, aguantan Monte Carlo y estaban pre-registradas. Veredicto del Validador.
A8: G3 | B8: demo de 8-12 semanas parecida a lo prometido; CEO fija dinero y pérdida máxima.
A9: G4 | B9: (mensual): si pierde más de lo escrito en 01.01.03, se para.
A10: GM | B10: (1 de septiembre de 2026): puerta de evaluación del primer mes. Decisión: arrancar demo, dar otra vuelta al bucle o replantear.

Sheet EQUIPO
A1: EQUIPO DE AGENTES — un modelo por puesto
A2: Regla 29: identificador exacto del modelo, nunca un alias, y ningun agente sin modelo.
A4: Agente | B4: Qué hace | C4: Qué NO puede hacer | D4: Modelo | E4: Respaldo
A5: Orquestador | B5: Reparte tareas por código, cierra contra criterio de hecho, escala excepciones al CEO | C5: Construir; validar su propio reparto | D5: Opus 5 | E5: Sonnet 5
A6: Investigador | B6: Barre fuentes (papers, libros, foros, GitHub, X); fichas de hipótesis | C6: Elegir sus propias fichas; tocar código o datos | D6: Sonnet 5 | E6: Haiku 4.5
A7: Constructor de datos | B7: Históricos, limpieza, los 3 cajones, costes reales | C7: Abrir el cajón reservado (OOS) | D7: Sonnet 5 | E7: Haiku 4.5
A8: Constructor de motor/bot | B8: Backtester, bot, ejecución desatendida | C8: Validar sus backtests; tocar el cajón reservado | D8: Sonnet 5 | E8: Opus 5 tras 2 atascos
A9: Crítico de código | B9: Revisa código ajeno; analiza gb2 (01.02.01) | C9: Revisar código propio | D9: Sonnet 5 (Opus 5 en código que toca dinero real) | E9: Sonnet 5
A10: Validador de estrategias | B10: Filtro de sentido, prueba OOS, Monte Carlo, veredictos pasa/no pasa | C10: Construir estrategias; suavizar veredictos | D10: Fable 5 | E10: Opus 5
A11: Arquitecto (puntual) | B11: Diseña el motor al arrancar Fase 03; revisa el planteamiento si el bucle falla 3 veces | C11: Trabajo del día a día | D11: Fable 5 | E11: Opus 5
A12: Secretario | B12: Informes, WBS, DECISIONES.md, LECCIONES.md, registro de pruebas | C12: Decidir | D12: Haiku 4.5 | E12: Sonnet 5
A14: Precios oficiales por millón de tokens (platform.claude.com, consultado 29/07/2026): Fable 5 (claude-fable-5) 10 $/50 $ · Opus 5 (claude-opus-5) 5 $/25 $ · Sonnet 5 (claude-sonnet-5) 3 $/15 $, con 2 $/10 $ hasta el 31/08/2026 · Haiku 4.5 (claude-haiku-4-5-20251001) 1 $/5 $. Contexto de 1M tokens salvo Haiku (200k).
A16: Aviso Fable 5: estuvo suspendido en junio de 2026 por controles de exportación y volvió el 1 de julio; además puede rechazar peticiones por sus filtros. Respaldo obligatorio (tarea 03.01.04).

Sheet REGLAS
A1: LAS 29 REGLAS — mandan sobre cualquier otra instruccion
A3: Nº | B3: REGLA
A4: 1 | B4: Toda tarea se ejecuta y se anuncia por su código WBS. Prohibidos identificadores opacos (t55).
A5: 2 | B5: No se inventan tareas: trabajo nuevo = primero se añade aquí con código y motivo. Subtareas dentro de alcance las crea el orquestador; tareas nuevas de primer nivel, solo en revisión semanal.
A6: 3 | B6: Los códigos son estables: una tarea empezada no se renumera jamás.
A7: 4 | B7: Se va en orden salvo tareas marcadas paralelas. Una tarea no se cierra sin cumplir su criterio de "hecho".
A8: 5 | B8: Nadie valida su propio trabajo. Los veredictos de estrategia los firma el Validador, no quien construyó.
A9: 6 | B9: Regla de no-ambigüedad: toda tarea debe poder ejecutarse sin adivinar nada. Si un agente tiene que suponer, la tarea vuelve al orquestador para reescribirse.
A10: 7 | B10: Pre-registro: ninguna variante de estrategia se prueba sin estar registrada antes. Se guardan TODAS las pruebas, también las fallidas.
A11: 8 | B11: Cada agente usa el modelo asignado en la sección Equipo, y su respaldo si ese modelo falla o rechaza la petición.
A12: 9 | B12: Restricción justificada, en dos niveles. Lo REVERSIBLE (archivos, carpetas, código, pruebas) empieza con permisos amplios: git lo deshace todo, y una restricción solo se añade tras un incidente real, anotada junto al incidente y revisada cada mes. Lo IRREVERSIBLE (dinero real, órdenes al broker, borrar el cajón de datos reservado, gastar dinero nuevo) lleva barrera desde el minuto uno y no se negocia. Manga ancha con lo que se puede deshacer, cero manga con lo que no.
A13: 10 | B13: Ficha de decisión del CEO: nada llega al CEO como "opina sobre esto". Toda decisión llega con: 1 línea de qué se decide · 2-4 opciones cerradas · la recomendada marcada con su motivo · qué pasa con cada opción · respuesta de una letra o un número. Ninguna ficha puede pedirle redactar, buscar o calcular nada. Si no cabe en media pantalla de móvil, vuelve atrás.
A14: 11 | B14: Cadencia de entregables: el WBS en texto se actualiza SIEMPRE que cambie algo (no es negociable). El Excel de vista del CEO se regenera solo para la revisión de los lunes y para las puertas.
A15: 12 | B15: Cada tirada autónoma cierra al menos una tarea que avanza el producto. La infraestructura que no desbloquee mecánicamente una tarea de producto se registra como deuda y no se ejecuta sin permiso del CEO. (gb2: 70% del esfuerzo al motor, 1 de 13 hipótesis probada, motor congelado dos veces sin frenarlo)
... A32: 29 | B32: Estados: pendiente | en_curso | hecha | bloqueada.

Sheet DECISIONES
A1: REGISTRO DE DECISIONES — solo se añade, nunca se reescribe (regla 21)
A3: Fecha | B3: Decisión | C3: Motivo
A4: 2026-07-29 | B4: Producto antes que motor; motor máx. 20% en paralelo | C4: Evitar la deriva de gb2
A5: 2026-07-29 | B5: Portafolio 3-5 mercados poco correlacionados | C5: Riesgo repartido + muestra
A6: 2026-07-29 | B6: Mercado y vela se deciden en G1 con datos | C6: Evitar corazonadas
A7: 2026-07-29 | B7: CEO: revisión semanal + puertas, sin firmas por tarea | C7: Dirección por excepción
A8: 2026-07-29 | B8: Broker después de G1; costes provisionales mientras | C8: Búsqueda enfocada
A9: 2026-07-29 | B9: WBS texto = fuente de verdad; Excel = vista del CEO | C9: Agentes leen texto
A10: 2026-07-29 | B10: Cada agente con su modelo según tarea (tabla Equipo); confirmar con análisis gb2 | C10: Replicar lo bueno de gb2 con criterio
A11: 2026-07-29 | B11: gb2 se analiza como información, no como copia (01.02.01) | C11: Lecciones sin contaminación
A12: 2026-07-29 | B12: Validación: 3 cajones (train/validación/OOS) + Monte Carlo + walk-forward, con pre-registro de variantes (máx. 5-7) y registro de fallidas | C12: Cuantas más variantes, más fácil que una gane por suerte; esto lo controla
A13: 2026-07-29 | B13: Bucle de investigación si nada pasa; a la 3ª vuelta sin éxito, revisión con el CEO | C13: Bucle sano, no infinito
A14: 2026-07-29 | B14: Regla de no-ambigüedad: tarea que obliga a adivinar vuelve al orquestador | C14: La ambigüedad fue causa del caos en gb2
... A29: 2026-07-30 | B29: El análisis del catálogo awesome-claude-code es trabajo de motor: entra en el carril del 20% y se limita a 1 tirada con máximo 4 propuestas | C29: Aplicación de la regla 12 a una petición del propio CEO

Sheet TRASPLANTE gb2
A1: TRASPLANTE DESDE gb2 (D6 = B, 30/07/2026)
A2: Ninguna pieza entra por ser buena en gb2: entra si pasa su prueba, ejecutada aqui.
A4: Pieza | B4: Qué se trae | C4: Criterio de aceptación (prueba ejecutada) | D4: Qué se descarta de ella
A5: T1 — Dataset histórico | B5: Precios validados 2015-2022 | C5: Se recalcula la cobertura, los duplicados y los spreads negativos AQUÍ, sin fiarse del informe. Prueba de cordura de precio: el oro debe estar en cientos/miles, no en decenas (en gb2 un divisor mal puesto lo puso a 17 $/onza) | D5: Todo lo que esté versionado en git: los datos se descargan, no se clonan (regla 24)
A6: T2 — Motor de backtest | B6: Costes reales nativos: entrada al precio de compra y salida al de venta, stops sin mejora de precio, financiación asimétrica con triple miércoles, dimensionado | C6: Se ejecuta con un caso hecho a mano cuyo resultado se calcula con lápiz y papel; si no coincide, no entra. Además se prueba que un stop nunca ejecuta a mejor precio del disparado | D6: Los drivers duplicados (scripts/backtest_f03*.py): en gb2 la lógica vivía en dos sitios con riesgo de divergencia
A7: T3 — Testbed de invarianza | B7: Prueba sintética con resultado de referencia fijo | C7: Se corre dos veces y da el mismo número; se altera el motor a propósito y debe cambiar. Un testbed que no detecta un cambio inducido no sirve | D7: El número de referencia de gb2: se genera uno nuevo aquí
A8: T4 — Guardias de datos reservados | B8: Bloqueo de acceso al cajón OOS | C8: Se intenta leer el cajón reservado por tres vías distintas (agente, script, terminal) y las tres deben bloquearse (regla 13). En gb2 estos sí mordían | D8: Los guardias que el propio informe señala como muertos o mal cableados
A9: T5 — Especificaciones e informes de las 13 hipótesis | B9: Material de partida para la fase 04 | C9: Ninguno: es material de lectura, no código. Advertencia obligatoria: 12 de las 13 nunca se probaron. Entran como hipótesis candidatas, no como conocimiento validado | D9: Cualquier conclusión sobre su calidad: no la hay
A11: NO se trae: la configuración de agentes, la cola de tareas, el historial de git, los ficheros de estado, los encadenadores de sesión ni ninguna documentación de gb2 como norma. Las lecciones ya están extraídas en las reglas 12 a 26.

Sheet LECCIONES
A1: LECCIONES APRENDIDAS
A3: ID | B3: Lección | C3: Origen
A4: L-001 | B4: Si un dato se puede calcular a partir de datos brutos disponibles, se calcula. Buscar el dato ya masticado pierde tiempo y devuelve fuentes flojas | C4: Revisión 02.03.01
A5: L-002 | B5: Toda conversión de unidades se aplica en la tabla final, no solo se explica en una nota al pie | C5: Revisión 02.03.01
A6: L-003 | B6: Medir el coste de entrar y salir sin medir el de mantener da una foto incompleta | C6: Revisión 02.03.01
A7: L-004 | B7: Los valores absolutos no se comparan entre activos distintos: se normalizan antes | C7: Revisión 02.03.01
A8: L-005 | B8: El modelo no aprende: acumula notas escritas. Si nadie escribe bien las notas, no mejora nada | C8: Análisis del vídeo, 29/07
A9: L-006 | B9: Si dos fuentes usan convenciones distintas (yen y franco invertidos), sus números tienen el signo cambiado. Verificar la convención antes de comparar | C9: Revisión Brief B
A10: L-007 | B10: Un nombre parecido no es el mismo instrumento: oro al contado ≠ futuro de oro; bitcoin contra Tether ≠ contra dólar | C10: Revisión Brief B
A11: L-008 | B11: Un umbral sobre una magnitud inestable necesita varias ventanas, no una | C11: Revisión Brief B
A12: L-009 | B12: Un guardia verificado por presencia y no por ejecución da falsa seguridad, que es peor que no tenerlo | C12: Auditoría gb2
A13: L-010 | B13: Los agentes no se activan solos porque tengan buena descripción: se activan si la cola contiene tareas de su tipo y el reparto enruta por tipo | C13: Auditoría gb2
A14: L-011 | B14: Tener una cola estricta no impide la deriva. gb2 la tenía ("trabajo que no está ahí no se ejecuta"), con IDs contiguos forzados por un hook, y aun así el 70% del esfuerzo se fue al motor. La cola controla QUÉ se ejecuta, no QUÉ se mete en la cola | C14: Auditoría gb2
A15: L-012 | B15: Dos agentes de acuerdo no son una prueba. En gb2 hubo tres diagnósticos seguidos del mismo componente, dos falsos; lo que los corrigió fue leer el código y reproducir el fallo, no debatir más | C15: Auditoría gb2

Sheet AUTONOMIA
A1: AUTONOMIA — que llega al CEO y que no
A3: CUANDO | B3: QUE PASA
A4: Lo cierra el equipo, sin consultar | B4: cerrar tareas que cumplen su criterio · orden de tareas ya aprobadas · subtareas dentro de alcance · descartar hipótesis o variantes que no pasan el filtro · reescribir tareas ambiguas · mover, corregir o borrar archivos para mantener el orden (git deshace).
A5: Llega al CEO, en el informe semanal | B5: mejoras del motor no previstas (sin aprobación, no se hacen) · tareas nuevas de primer nivel.
A6: Llega al CEO como excepción inmediata (se para hasta respuesta) | B6: gasto nuevo (datos de pago, VPS, broker, créditos extra) · cualquier cosa con dinero real · bloqueo de más de 24 h · 3 vueltas del bucle de hipótesis sin éxito.
A7: Llega al CEO solo en una puerta | B7: cambiar de mercado, de tamaño de vela o de planteamiento.
A9: FORMATO OBLIGATORIO DE FICHA DE DECISION (regla 10)
A10: D[n] — [Qué se decide, una línea] A) [opción] B) [opción] C) [opción] RECOMENDADA: [letra] — [motivo en una línea] SI ELIGES OTRA: [consecuencia de cada una, una línea] BLOQUEA: [qué tareas no pueden avanzar hasta que respondas] RESPUESTA: [una letra]

Sheet LIMITES CEO
A1: LIMITES DEL CEO
A4: Horizonte: 1 mes. Evaluación el 1 de septiembre (puerta GM).
A5: Tiempo del CEO: 1 hora, lunes.
A6: Dinero real (pendiente de confirmar, ficha D5): capital 1.000-2.000 €, parada dura propuesta en -25%. Nota: el CEO mencionó tolerar caídas del 50-60%, incompatible con parar en -25%; recuperarse de -25% exige +33%, de -50% exige +100% y de -60% exige +150%.
